<?xml version="1.0" ?>
<sdf version="1.6">
<model name="scuba">
    <link name="base_link">
      <inertial>
        <pose>0 0 0 0 0 0</pose>
        <mass>13.0</mass>
        <inertia>
          <ixx>0.26</ixx>
          <ixy>0</ixy>
          <ixz>0</ixz>
          <iyy>0.23</iyy>
          <iyz>0</iyz>
          <izz>0.37</izz>
        </inertia>
      </inertial>

      <visual name="base_link_visual">
        <geometry>
          <box>
            <size>0.457 0.575 0.05</size>
          </box>
        </geometry>
      </visual>

      <collision name="base_link_collision">
        <pose>0 0 0 0 0 0</pose>
        <geometry>
          <box>
            <size>0.457 0.575 0.05</size>
          </box>
        </geometry>
      </collision>

      <sensor name="imu_sensor" type="imu">
        <pose>0 0 0 0 0 0</pose>
        <always_on>1</always_on>
        <update_rate>10.0</update_rate>
      </sensor>
    </link>

     <!-- Hydrodynamics plugin -->
    <plugin
        filename="ignition-gazebo-hydrodynamics-system"
        name="ignition::gazebo::systems::Hydrodynamics">
      <link_name>base_link</link_name>
      <water_density>1000.0</water_density>
      <!-- Added mass: -->
      <xDotU>0</xDotU>
      <yDotV>0</yDotV>
      <zDotW>0</zDotW>
      <kDotP>0</kDotP>
      <mDotQ>0</mDotQ>
      <nDotR>0</nDotR> 
      <!-- First order stability derivative: -->
      <xU>0</xU>
      <yV>0</yV>
      <zW>0</zW>
      <kP>0</kP>
      <mQ>0</mQ>
      <nR>0</nR>
      <!-- Second order stability derivative: -->
      <xUabsU>-58.42</xUabsU>
      <yVabsV>-55.137</yVabsV>
      <zWabsW>-124.818</zWabsW>
      <kPabsP>-4.0</kPabsP>
      <mQabsQ>-4.0</mQabsQ>
      <nRabsR>-4.0</nRabsR>
    </plugin>

    <link name="thruster1">
      <pose>0 0 0 0 0 0</pose>
      <visual name="thruster_prop_visual">
        <pose>0 0 0 0 0 0</pose>
        <geometry>
          <box>
             <size>0.2 0.2 0.2</size>
          </box>
        </geometry>
      </visual>
      <inertial>
        <mass>0.002</mass>
        <inertia>
          <ixx>0.001</ixx>
          <ixy>0</ixy>
          <ixz>0</ixz>
          <iyy>0.001</iyy>
          <iyz>0</iyz>
          <izz>0.001</izz>
        </inertia>
      </inertial>
    </link>

    <joint name="thruster1_joint" type="revolute">
      <parent>base_link</parent>
      <child>thruster1</child>
      <axis>
        <xyz>0 0 -1</xyz>
      </axis>
    </joint>

    <plugin
        filename="ignition-gazebo-thruster-system"
        name="ignition::gazebo::systems::Thruster">
      <namespace>bluerov2_heavy</namespace>
      <joint_name>thruster1_joint</joint_name>
      <thrust_coefficient>0.02</thrust_coefficient>
      <fluid_density>1000.0</fluid_density>
      <propeller_diameter>0.1</propeller_diameter>
      <velocity_control>true</velocity_control>
      <use_angvel_cmd>true</use_angvel_cmd>
    </plugin>
</model>
</sdf>