<?xml version="1.0" ?>
<!-- =================================================================================== -->
<!-- |    This document was autogenerated by xacro from /home/ubuntu/dev_ws/install/auv_description/share/auv_description/model/auv.xacro | -->
<!-- |    EDITING THIS FILE BY HAND IS NOT RECOMMENDED                                 | -->
<!-- =================================================================================== -->
<robot name="auv">
  <!-- Specify some standard inertial calculations https://en.wikipedia.org/wiki/List_of_moments_of_inertia -->
  <!-- base -->
  <link name="dummy">
  </link>
  <link name="base_link">
    <inertial>
      <mass value="1.14395"/>
      <inertia ixx="0.095329" ixy="0" ixz="0" iyy="0.381317" iyz="0" izz="0.476646"/>
    </inertial>
    <visual>
      <geometry>
        <box size="2.0 1.0 0.5"/>
      </geometry>
    </visual>
    <collision>
      <geometry>
        <box size="2.0 1.0 0.5"/>
      </geometry>
    </collision>
  </link>
  <joint name="dummy_joint" type="fixed">
    <parent link="dummy"/>
    <child link="base_link"/>
  </joint>
  <gazebo reference="base_link">
    <visual>
      <material>
        <ambient>1 0 0 1</ambient>
        <diffuse>1 0 0 1</diffuse>
        <specular>1 0 0 1</specular>
      </material>
    </visual>
  </gazebo>
  <link name="fl_link">
    <inertial>
      <mass value="1"/>
      <inertia ixx="0.043333" ixy="0" ixz="0" iyy="0.043333" iyz="0" izz="0.08"/>
    </inertial>
    <visual>
      <geometry>
        <cylinder length="0.2" radius="0.4"/>
      </geometry>
    </visual>
    <collision>
      <geometry>
        <cylinder length="0.2" radius="0.4"/>
      </geometry>
    </collision>
  </link>
  <joint name="fl_joint" type="continuous">
    <origin rpy="1.5707 0.0 0.0" xyz="0.5 -0.6 0.0"/>
    <parent link="base_link"/>
    <child link="fl_link"/>
    <axis xyz="0.0 0.0 1.0"/>
  </joint>
  <link name="fr_link">
    <inertial>
      <mass value="1"/>
      <inertia ixx="0.043333" ixy="0" ixz="0" iyy="0.043333" iyz="0" izz="0.08"/>
    </inertial>
    <visual>
      <geometry>
        <cylinder length="0.2" radius="0.4"/>
      </geometry>
    </visual>
    <collision>
      <geometry>
        <cylinder length="0.2" radius="0.4"/>
      </geometry>
    </collision>
  </link>
  <joint name="fr_joint" type="continuous">
    <origin rpy="1.5707 0.0 0.0" xyz="0.5 0.6 0.0"/>
    <parent link="base_link"/>
    <child link="fr_link"/>
    <axis xyz="0.0 0.0 1.0"/>
  </joint>
  <!-- caster -->
  <link name="caster_link">
    <inertial>
      <origin rpy="0 0 0" xyz="0 0 0"/>
      <mass value="1e-06"/>
      <inertia ixx="1.6e-08" ixy="0.0" ixz="0.0" iyy="1.6e-08" iyz="0.0" izz="1.6e-08"/>
    </inertial>
    <visual>
      <geometry>
        <sphere radius="0.2"/>
      </geometry>
    </visual>
    <collision>
      <geometry>
        <sphere radius="0.2"/>
      </geometry>
    </collision>
  </link>
  <joint name="caster_joint" type="fixed">
    <origin rpy="0 0 0" xyz="-0.8 0 -0.2"/>
    <parent link="base_link"/>
    <child link="caster_link"/>
  </joint>
  <!-- plugins -->
  <gazebo>
    <plugin filename="ignition-gazebo-diff-drive-system" name="ignition::gazebo::systems::DiffDrive">
      <left_joint>fl_joint</left_joint>
      <right_joint>fr_joint</right_joint>
      <wheel_separation>1</wheel_separation>
      <wheel_radius>0.4</wheel_radius>
      <odom_publish_frequency>1</odom_publish_frequency>
      <topic>cmd_vel</topic>
    </plugin>
  </gazebo>
  <gazebo reference="base_link">
    <sensor name="imu_sensor" type="imu">
      <always_on>1</always_on>
      <update_rate>1</update_rate>
      <visualize>true</visualize>
      <topic>imu</topic>
    </sensor>
  </gazebo>
</robot>
