<?xml version="1.0" ?>
<!-- =================================================================================== -->
<!-- |    This document was autogenerated by xacro from rover.xacro                    | -->
<!-- |    EDITING THIS FILE BY HAND IS NOT RECOMMENDED                                 | -->
<!-- =================================================================================== -->
<robot name="rover">
  <!-- dummy -->
  <link name="base_footprint"/>
  <link name="base_link">
    <inertial>
      <origin rpy="0 0 0" xyz="0 0 0"/>
      <mass value="2"/>
      <inertia ixx="0.18166666666666667" ixy="0.0" ixz="0.0" iyy="0.6816666666666666" iyz="0.0" izz="0.8333333333333333"/>
    </inertial>
    <visual>
      <geometry>
        <box size="2.0 1.0 0.3"/>
      </geometry>
    </visual>
    <collision>
      <geometry>
        <box size="2.0 1.0 0.3"/>
      </geometry>
    </collision>
  </link>
  <joint name="dummy_joint" type="fixed">
    <parent link="base_footprint"/>
    <child link="base_link"/>
  </joint>
  <gazebo reference="base_link">
    <visual>
      <material>
        <ambient>1 0 0 1</ambient>
        <diffuse>1 0 0 1</diffuse>
        <specular>1 0 0 1</specular>
      </material>
    </visual>
  </gazebo>
  <link name="fl_link">
    <inertial>
      <origin rpy="0 0 0" xyz="0 0 0"/>
      <mass value="1.2"/>
      <inertia ixx="0.036" ixy="0.0" ixz="0.0" iyy="0.036" iyz="0.0" izz="0.054"/>
    </inertial>
    <visual>
      <geometry>
        <cylinder length="0.3" radius="0.3"/>
      </geometry>
    </visual>
    <collision>
      <geometry>
        <cylinder length="0.3" radius="0.3"/>
      </geometry>
    </collision>
  </link>
  <joint name="fl_joint" type="continuous">
    <origin rpy="1.5707963267948966 3.141592653589793 3.141592653589793" xyz="0.7 0.65 0.0"/>
    <parent link="base_link"/>
    <child link="fl_link"/>
    <axis xyz="0.0 0.0 1.0"/>
  </joint>
  <link name="fr_link">
    <inertial>
      <origin rpy="0 0 0" xyz="0 0 0"/>
      <mass value="1.2"/>
      <inertia ixx="0.036" ixy="0.0" ixz="0.0" iyy="0.036" iyz="0.0" izz="0.054"/>
    </inertial>
    <visual>
      <geometry>
        <cylinder length="0.3" radius="0.3"/>
      </geometry>
    </visual>
    <collision>
      <geometry>
        <cylinder length="0.3" radius="0.3"/>
      </geometry>
    </collision>
  </link>
  <joint name="fr_joint" type="continuous">
    <origin rpy="1.5707963267948966 3.141592653589793 3.141592653589793" xyz="0.7 -0.65 0.0"/>
    <parent link="base_link"/>
    <child link="fr_link"/>
    <axis xyz="0.0 0.0 1.0"/>
  </joint>
  <link name="caster_link">
    <inertial>
      <origin rpy="0 0 0" xyz="0 0 0"/>
      <mass value="1.2"/>
      <inertia ixx="0.043199999999999995" ixy="0.0" ixz="0.0" iyy="0.043199999999999995" iyz="0.0" izz="0.043199999999999995"/>
    </inertial>
    <visual>
      <geometry>
        <sphere radius="0.3"/>
      </geometry>
    </visual>
    <collision>
      <geometry>
        <sphere radius="0.3"/>
      </geometry>
    </collision>
  </link>
  <joint name="caster_joint" type="fixed">
    <origin rpy="0 0 0" xyz="-0.7 0 0"/>
    <parent link="base_link"/>
    <child link="caster_link"/>
  </joint>
  <gazebo reference="caster_link">
    <surface>
      <friction>
        <ode>
          <mu>0.01</mu>
          <mu2>0.01</mu2>
        </ode>
      </friction>
    </surface>
  </gazebo>
  <!-- plugins -->
  <gazebo>
    <plugin filename="ignition-gazebo-diff-drive-system" name="ignition::gazebo::systems::DiffDrive">
      <left_joint>fl_joint</left_joint>
      <right_joint>fr_joint</right_joint>
      <wheel_separation>1.0</wheel_separation>
      <wheel_radius>0.3</wheel_radius>
      <odom_publish_frequency>100.0</odom_publish_frequency>
      <topic>cmd_vel</topic>
    </plugin>
    <plugin filename="ignition-gazebo-pose-publisher-system" name="ignition::gazebo::systems::PosePublisher">
      <publish_link_pose>false</publish_link_pose>
      <publish_collision_pose>false</publish_collision_pose>
      <publish_visual_pose>false</publish_visual_pose>
      <publish_sensor_pose>false</publish_sensor_pose>
      <publish_nested_model_pose>true</publish_nested_model_pose>
      <update_frequency>100.0</update_frequency>
      <use_pose_vector_msg>false</use_pose_vector_msg>
    </plugin>
  </gazebo>
  <!-- sensors -->
  <gazebo reference="base_link">
    <sensor name="imu_sensor" type="imu">
      <always_on>true</always_on>
      <update_rate>100.0</update_rate>
      <visualize>true</visualize>
      <topic>/model/rover/imu</topic>
      <angular_velocity>
        <x>
          <noise type="none"/>
        </x>
        <y>
          <noise type="none"/>
        </y>
        <z>
          <noise type="none"/>
        </z>
      </angular_velocity>
      <linear_acceleration>
        <x>
          <noise type="none"/>
        </x>
        <y>
          <noise type="none"/>
        </y>
        <z>
          <noise type="none"/>
        </z>
      </linear_acceleration>
    </sensor>
  </gazebo>
</robot>
