<sdf version='1.9'>
  <model name='rover'>
    <link name='base_footprint'>
      <inertial>
        <pose>-0.2625 0 0 0 0 0</pose>
        <mass>3.2000000000000002</mass>
        <inertia>
          <ixx>0.22486666666666669</ixx>
          <ixy>0</ixy>
          <ixz>0</ixz>
          <iyy>1.092366666666666</iyy>
          <iyz>0</iyz>
          <izz>1.2440333333333331</izz>
        </inertia>
      </inertial>
      <collision name='base_footprint_fixed_joint_lump__base_link_collision'>
        <pose>0 0 0 0 0 0</pose>
        <geometry>
          <box>
            <size>2 1 0.3</size>
          </box>
        </geometry>
        <surface>
          <contact>
            <ode/>
          </contact>
          <friction>
            <ode/>
          </friction>
        </surface>
      </collision>
      <collision name='base_footprint_fixed_joint_lump__caster_link_collision_1'>
        <pose>-0.7 0 0 0 0 0</pose>
        <geometry>
          <sphere>
            <radius>0.29999999999999999</radius>
          </sphere>
        </geometry>
        <surface>
          <contact>
            <ode/>
          </contact>
          <friction>
            <ode/>
          </friction>
        </surface>
      </collision>
      <visual name='base_footprint_fixed_joint_lump__base_link_visual'>
        <pose>0 0 0 0 0 0</pose>
        <geometry>
          <box>
            <size>2 1 0.3</size>
          </box>
        </geometry>
        <material>
          <ambient>1 0 0 1</ambient>
          <diffuse>1 0 0 1</diffuse>
          <specular>1 0 0 1</specular>
        </material>
      </visual>
      <visual name='base_footprint_fixed_joint_lump__caster_link_visual_1'>
        <pose>-0.7 0 0 0 0 0</pose>
        <geometry>
          <sphere>
            <radius>0.29999999999999999</radius>
          </sphere>
        </geometry>
      </visual>
      <sensor name='imu_sensor' type='imu'>
        <always_on>true</always_on>
        <update_rate>100</update_rate>
        <visualize>true</visualize>
        <topic>/model/rover/imu</topic>
        <pose>0 0 0 0 -0 0</pose>
        <angular_velocity>
          <x>
            <noise type='none'/>
          </x>
          <y>
            <noise type='none'/>
          </y>
          <z>
            <noise type='none'/>
          </z>
        </angular_velocity>
        <linear_acceleration>
          <x>
            <noise type='none'/>
          </x>
          <y>
            <noise type='none'/>
          </y>
          <z>
            <noise type='none'/>
          </z>
        </linear_acceleration>
      </sensor>
      <surface>
        <friction>
          <ode>
            <mu>0.01</mu>
            <mu2>0.01</mu2>
          </ode>
        </friction>
      </surface>
    </link>
    <joint name='fl_joint' type='revolute'>
      <pose relative_to='base_footprint'>0.7 0.65 0 -1.570796326794897 1.224646799147353e-16 -1.224646799147353e-16</pose>
      <parent>base_footprint</parent>
      <child>fl_link</child>
      <axis>
        <xyz>0 0 1</xyz>
        <limit>
          <lower>-10000000000000000</lower>
          <upper>10000000000000000</upper>
        </limit>
        <dynamics>
          <spring_reference>0</spring_reference>
          <spring_stiffness>0</spring_stiffness>
        </dynamics>
      </axis>
    </joint>
    <link name='fl_link'>
      <pose relative_to='fl_joint'>0 0 0 0 0 0</pose>
      <inertial>
        <pose>0 0 0 0 0 0</pose>
        <mass>1.2</mass>
        <inertia>
          <ixx>0.035999999999999997</ixx>
          <ixy>0</ixy>
          <ixz>0</ixz>
          <iyy>0.035999999999999997</iyy>
          <iyz>0</iyz>
          <izz>0.053999999999999999</izz>
        </inertia>
      </inertial>
      <collision name='fl_link_collision'>
        <pose>0 0 0 0 0 0</pose>
        <geometry>
          <cylinder>
            <length>0.29999999999999999</length>
            <radius>0.29999999999999999</radius>
          </cylinder>
        </geometry>
      </collision>
      <visual name='fl_link_visual'>
        <pose>0 0 0 0 0 0</pose>
        <geometry>
          <cylinder>
            <length>0.29999999999999999</length>
            <radius>0.29999999999999999</radius>
          </cylinder>
        </geometry>
      </visual>
    </link>
    <joint name='fr_joint' type='revolute'>
      <pose relative_to='base_footprint'>0.7 -0.65 0 -1.570796326794897 1.224646799147353e-16 -1.224646799147353e-16</pose>
      <parent>base_footprint</parent>
      <child>fr_link</child>
      <axis>
        <xyz>0 0 1</xyz>
        <limit>
          <lower>-10000000000000000</lower>
          <upper>10000000000000000</upper>
        </limit>
        <dynamics>
          <spring_reference>0</spring_reference>
          <spring_stiffness>0</spring_stiffness>
        </dynamics>
      </axis>
    </joint>
    <link name='fr_link'>
      <pose relative_to='fr_joint'>0 0 0 0 0 0</pose>
      <inertial>
        <pose>0 0 0 0 0 0</pose>
        <mass>1.2</mass>
        <inertia>
          <ixx>0.035999999999999997</ixx>
          <ixy>0</ixy>
          <ixz>0</ixz>
          <iyy>0.035999999999999997</iyy>
          <iyz>0</iyz>
          <izz>0.053999999999999999</izz>
        </inertia>
      </inertial>
      <collision name='fr_link_collision'>
        <pose>0 0 0 0 0 0</pose>
        <geometry>
          <cylinder>
            <length>0.29999999999999999</length>
            <radius>0.29999999999999999</radius>
          </cylinder>
        </geometry>
      </collision>
      <visual name='fr_link_visual'>
        <pose>0 0 0 0 0 0</pose>
        <geometry>
          <cylinder>
            <length>0.29999999999999999</length>
            <radius>0.29999999999999999</radius>
          </cylinder>
        </geometry>
      </visual>
    </link>
    <static>false</static>
    <plugin name='ignition::gazebo::systems::DiffDrive' filename='ignition-gazebo-diff-drive-system'>
      <left_joint>fl_joint</left_joint>
      <right_joint>fr_joint</right_joint>
      <wheel_separation>1.0</wheel_separation>
      <wheel_radius>0.3</wheel_radius>
      <odom_publish_frequency>100.0</odom_publish_frequency>
      <topic>cmd_vel</topic>
    </plugin>
    <plugin name='ignition::gazebo::systems::PosePublisher' filename='ignition-gazebo-pose-publisher-system'>
      <publish_link_pose>false</publish_link_pose>
      <publish_collision_pose>false</publish_collision_pose>
      <publish_visual_pose>false</publish_visual_pose>
      <publish_sensor_pose>false</publish_sensor_pose>
      <publish_nested_model_pose>true</publish_nested_model_pose>
      <update_frequency>100.0</update_frequency>
      <use_pose_vector_msg>false</use_pose_vector_msg>
    </plugin>
  </model>
</sdf>
